<sdf version='1.10'>
  <world name='empty'>
    <physics name='1ms' type='ignored'>
      <max_step_size>0.001</max_step_size>
      <real_time_factor>1</real_time_factor>
      <real_time_update_rate>1000</real_time_update_rate>
    </physics>
    <plugin name='gz::sim::systems::Physics' filename='gz-sim-physics-system'/>
    <plugin name='gz::sim::systems::UserCommands' filename='gz-sim-user-commands-system'/>
    <plugin name='gz::sim::systems::SceneBroadcaster' filename='gz-sim-scene-broadcaster-system'/>
    <plugin name='gz::sim::systems::Contact' filename='gz-sim-contact-system'/>
    <plugin filename = "gz-sim-apply-link-wrench-system" name = "gz::sim::systems::ApplyLinkWrench"/>
    <gravity>0 0 -9.8000000000000007</gravity>
    <magnetic_field>5.5644999999999998e-06 2.2875799999999999e-05 -4.2388400000000002e-05</magnetic_field>
    <atmosphere type='adiabatic'/>
    <scene>
      <ambient>0.400000006 0.400000006 0.400000006 1</ambient>
      <background>0.699999988 0.699999988 0.699999988 1</background>
      <shadows>true</shadows>
    </scene>
    <model name='ground_plane'>
      <static>true</static>
      <link name='link'>
        <collision name='collision'>
          <geometry>
            <plane>
              <normal>0 0 1</normal>
              <size>100 100</size>
            </plane>
          </geometry>
          <surface>
            <friction>
              <ode/>
            </friction>
            <bounce/>
            <contact/>
          </surface>
        </collision>
        <visual name='visual'>
          <geometry>
            <plane>
              <normal>0 0 1</normal>
              <size>100 100</size>
            </plane>
          </geometry>
          <material>
            <ambient>0.800000012 0.800000012 0.800000012 1</ambient>
            <diffuse>0.800000012 0.800000012 0.800000012 1</diffuse>
            <specular>0.800000012 0.800000012 0.800000012 1</specular>
          </material>
        </visual>
        <pose>0 0 0 0 0 0</pose>
        <inertial>
          <pose>0 0 0 0 0 0</pose>
          <mass>1</mass>
          <inertia>
            <ixx>1</ixx>
            <ixy>0</ixy>
            <ixz>0</ixz>
            <iyy>1</iyy>
            <iyz>0</iyz>
            <izz>1</izz>
          </inertia>
        </inertial>
        <enable_wind>false</enable_wind>
      </link>
      <pose>0 0 0 0 0 0</pose>
      <self_collide>false</self_collide>
    </model>
    <model name='cartpole_balancer'>
      <link name='base_link'>
        <inertial>
          <pose>0 0 0.14999999999999999 0 0 0</pose>
          <mass>5</mass>
          <inertia>
            <ixx>0.083333333333333329</ixx>
            <ixy>0</ixy>
            <ixz>0</ixz>
            <iyy>0.1666666666666666</iyy>
            <iyz>0</iyz>
            <izz>0.2166666666666667</izz>
          </inertia>
        </inertial>
        <collision name='base_link_fixed_joint_lump__base_link_collision'>
          <pose>0 0 0.14999999999999999 0 0 0</pose>
          <geometry>
            <box>
              <size>0.59999999999999998 0.40000000000000002 0.20000000000000001</size>
            </box>
          </geometry>
          <surface>
            <friction>
              <ode/>
            </friction>
            <bounce/>
            <contact/>
          </surface>
        </collision>
        <visual name='base_link_fixed_joint_lump__visual_visual'>
          <pose>0 0 0.14999999999999999 0 0 0</pose>
          <geometry>
            <box>
              <size>0.59999999999999998 0.40000000000000002 0.20000000000000001</size>
            </box>
          </geometry>
          <material>
            <diffuse>1 0 0 1</diffuse>
            <ambient>1 0 0 1</ambient>
          </material>
        </visual>
        <pose>0 0 0 0 0 0</pose>
        <enable_wind>false</enable_wind>
      </link>
      <joint name='cartpole_base_joint' type='revolute'>
        <pose>0 0 0 0 0 0</pose>
        <parent>base_link</parent>
        <child>cartpole_link</child>
        <axis>
          <xyz>0 1 0</xyz>
          <limit>
            <lower>-0.69999999999999996</lower>
            <upper>0.69999999999999996</upper>
          </limit>
          <dynamics>
            <spring_reference>0</spring_reference>
            <spring_stiffness>0</spring_stiffness>
            <damping>0.5</damping>
            <friction>0</friction>
          </dynamics>
        </axis>
      </joint>
      <link name='cartpole_link'>
        <pose>0 5.8774717541114375e-39 0.25 6.4921011317425931e-45 -2.3361752918385383e-23 -7.5833431280470289e-68</pose>
        <inertial>
          <pose>0 0 0.36666666666666681 0 0 0</pose>
          <mass>0.59999999999999998</mass>
          <inertia>
            <ixx>0.0047472916666666393</ixx>
            <ixy>0</ixy>
            <ixz>0</ixz>
            <iyy>0.0047472916666666393</iyy>
            <iyz>0</iyz>
            <izz>8.125000000000001e-05</izz>
          </inertia>
        </inertial>
        <collision name='cartpole_link_collision'>
          <pose>0 0 0.20000000000000001 0 0 0</pose>
          <geometry>
            <cylinder>
              <length>0.40000000000000002</length>
              <radius>0.0050000000000000001</radius>
            </cylinder>
          </geometry>
          <surface>
            <friction>
              <ode/>
            </friction>
            <bounce/>
            <contact/>
          </surface>
        </collision>
        <collision name='cartpole_link_fixed_joint_lump__bob_link_collision_1'>
          <pose>0 0 0.40000000000000002 0 0 0</pose>
          <geometry>
            <sphere>
              <radius>0.02</radius>
            </sphere>
          </geometry>
          <surface>
            <friction>
              <ode/>
            </friction>
            <bounce/>
            <contact/>
          </surface>
        </collision>
        <visual name='cartpole_link_fixed_joint_lump__visual_visual'>
          <pose>0 0 0.20000000000000001 0 0 0</pose>
          <geometry>
            <cylinder>
              <length>0.40000000000000002</length>
              <radius>0.0050000000000000001</radius>
            </cylinder>
          </geometry>
          <material>
            <diffuse>0 0 1 1</diffuse>
            <ambient>0 0 1 1</ambient>
          </material>
        </visual>
        <visual name='cartpole_link_fixed_joint_lump__visual_visual_1'>
          <pose>0 0 0.40000000000000002 0 0 0</pose>
          <geometry>
            <sphere>
              <radius>0.02</radius>
            </sphere>
          </geometry>
          <material>
            <diffuse>1 1 0 1</diffuse>
            <ambient>1 1 0 1</ambient>
          </material>
        </visual>
        <enable_wind>false</enable_wind>
      </link>
      <joint name='front_left_wheel_joint' type='revolute'>
        <pose>0 0 0 0 0 0</pose>
        <parent>base_link</parent>
        <child>front_left_wheel_link</child>
        <axis>
          <xyz>0 1 0</xyz>
          <limit>
            <lower>-inf</lower>
            <upper>inf</upper>
            <effort>inf</effort>
            <velocity>inf</velocity>
            <stiffness>100000000</stiffness>
            <dissipation>1</dissipation>
          </limit>
          <dynamics>
            <spring_reference>0</spring_reference>
            <spring_stiffness>0</spring_stiffness>
            <damping>0</damping>
            <friction>0</friction>
          </dynamics>
        </axis>
      </joint>
      <link name='front_left_wheel_link'>
        <pose>0.14999999999999999 0.20000000000000001 0.049999999999999989 -8.3981465539371425e-43 3.022063593652105e-21 -1.2689866477404162e-63</pose>
        <inertial>
          <pose>0 0 0 0 0 0</pose>
          <mass>1</mass>
          <inertia>
            <ixx>0.001458333333333333</ixx>
            <ixy>0</ixy>
            <ixz>0</ixz>
            <iyy>0.001458333333333333</iyy>
            <iyz>0</iyz>
            <izz>0.00125</izz>
          </inertia>
        </inertial>
        <collision name='front_left_wheel_link_collision'>
          <pose>0 0 0 1.5707963267948959 0 0</pose>
          <geometry>
            <cylinder>
              <length>0.10000000000000001</length>
              <radius>0.050000000000000003</radius>
            </cylinder>
          </geometry>
          <surface>
            <friction>
              <ode/>
            </friction>
            <bounce/>
            <contact/>
          </surface>
        </collision>
        <visual name='front_left_wheel_link_fixed_joint_lump__visual_2_visual'>
          <pose>0 0 0 1.5707963267948959 0 0</pose>
          <geometry>
            <cylinder>
              <length>0.10000000000000001</length>
              <radius>0.050000000000000003</radius>
            </cylinder>
          </geometry>
          <material>
            <diffuse>1 0 0 1</diffuse>
            <ambient>1 0 0 1</ambient>
          </material>
        </visual>
        <enable_wind>false</enable_wind>
      </link>
      <joint name='front_right_wheel_joint' type='revolute'>
        <pose>0 0 0 0 0 0</pose>
        <parent>base_link</parent>
        <child>front_right_wheel_link</child>
        <axis>
          <xyz>0 1 0</xyz>
          <limit>
            <lower>-inf</lower>
            <upper>inf</upper>
            <effort>inf</effort>
            <velocity>inf</velocity>
            <stiffness>100000000</stiffness>
            <dissipation>1</dissipation>
          </limit>
          <dynamics>
            <spring_reference>0</spring_reference>
            <spring_stiffness>0</spring_stiffness>
            <damping>0</damping>
            <friction>0</friction>
          </dynamics>
        </axis>
      </joint>
      <link name='front_right_wheel_link'>
        <pose>0.14999999999999999 -0.20000000000000001 0.049999999999999989 3.8835203561714517e-43 -1.3974804331189625e-21 -2.713571854684394e-64</pose>
        <inertial>
          <pose>0 0 0 0 0 0</pose>
          <mass>1</mass>
          <inertia>
            <ixx>0.001458333333333333</ixx>
            <ixy>0</ixy>
            <ixz>0</ixz>
            <iyy>0.001458333333333333</iyy>
            <iyz>0</iyz>
            <izz>0.00125</izz>
          </inertia>
        </inertial>
        <collision name='front_right_wheel_link_collision'>
          <pose>0 0 0 1.5707963267948959 0 0</pose>
          <geometry>
            <cylinder>
              <length>0.10000000000000001</length>
              <radius>0.050000000000000003</radius>
            </cylinder>
          </geometry>
          <surface>
            <friction>
              <ode/>
            </friction>
            <bounce/>
            <contact/>
          </surface>
        </collision>
        <visual name='front_right_wheel_link_fixed_joint_lump__visual_2_visual'>
          <pose>0 0 0 1.5707963267948959 0 0</pose>
          <geometry>
            <cylinder>
              <length>0.10000000000000001</length>
              <radius>0.050000000000000003</radius>
            </cylinder>
          </geometry>
          <material>
            <diffuse>1 0 0 1</diffuse>
            <ambient>1 0 0 1</ambient>
          </material>
        </visual>
        <enable_wind>false</enable_wind>
      </link>
      <joint name='rear_left_wheel_joint' type='revolute'>
        <pose>0 0 0 0 0 0</pose>
        <parent>base_link</parent>
        <child>rear_left_wheel_link</child>
        <axis>
          <xyz>0 1 0</xyz>
          <limit>
            <lower>-inf</lower>
            <upper>inf</upper>
            <effort>inf</effort>
            <velocity>inf</velocity>
            <stiffness>100000000</stiffness>
            <dissipation>1</dissipation>
          </limit>
          <dynamics>
            <spring_reference>0</spring_reference>
            <spring_stiffness>0</spring_stiffness>
            <damping>0</damping>
            <friction>0</friction>
          </dynamics>
        </axis>
      </joint>
      <link name='rear_left_wheel_link'>
        <pose>-0.14999999999999999 0.20000000000000001 0.049999999999999989 -8.4143263694486834e-43 3.027885882069603e-21 -1.2738810010589824e-63</pose>
        <inertial>
          <pose>0 0 0 0 0 0</pose>
          <mass>1</mass>
          <inertia>
            <ixx>0.001458333333333333</ixx>
            <ixy>0</ixy>
            <ixz>0</ixz>
            <iyy>0.001458333333333333</iyy>
            <iyz>0</iyz>
            <izz>0.00125</izz>
          </inertia>
        </inertial>
        <collision name='rear_left_wheel_link_collision'>
          <pose>0 0 0 1.5707963267948959 0 0</pose>
          <geometry>
            <cylinder>
              <length>0.10000000000000001</length>
              <radius>0.050000000000000003</radius>
            </cylinder>
          </geometry>
          <surface>
            <friction>
              <ode/>
            </friction>
            <bounce/>
            <contact/>
          </surface>
        </collision>
        <visual name='rear_left_wheel_link_fixed_joint_lump__visual_2_visual'>
          <pose>0 0 0 1.5707963267948959 0 0</pose>
          <geometry>
            <cylinder>
              <length>0.10000000000000001</length>
              <radius>0.050000000000000003</radius>
            </cylinder>
          </geometry>
          <material>
            <diffuse>1 0 0 1</diffuse>
            <ambient>1 0 0 1</ambient>
          </material>
        </visual>
        <enable_wind>false</enable_wind>
      </link>
      <joint name='rear_right_wheel_joint' type='revolute'>
        <pose>0 0 0 0 0 0</pose>
        <parent>base_link</parent>
        <child>rear_right_wheel_link</child>
        <axis>
          <xyz>0 1 0</xyz>
          <limit>
            <lower>-inf</lower>
            <upper>inf</upper>
            <effort>inf</effort>
            <velocity>inf</velocity>
            <stiffness>100000000</stiffness>
            <dissipation>1</dissipation>
          </limit>
          <dynamics>
            <spring_reference>0</spring_reference>
            <spring_stiffness>0</spring_stiffness>
            <damping>0</damping>
            <friction>0</friction>
          </dynamics>
        </axis>
      </joint>
      <link name='rear_right_wheel_link'>
        <pose>-0.14999999999999999 -0.20000000000000001 0.049999999999999989 3.8755941669953255e-43 -1.3946282028569957e-21 -2.7025064640598732e-64</pose>
        <inertial>
          <pose>0 0 0 0 0 0</pose>
          <mass>1</mass>
          <inertia>
            <ixx>0.001458333333333333</ixx>
            <ixy>0</ixy>
            <ixz>0</ixz>
            <iyy>0.001458333333333333</iyy>
            <iyz>0</iyz>
            <izz>0.00125</izz>
          </inertia>
        </inertial>
        <collision name='rear_right_wheel_link_collision'>
          <pose>0 0 0 1.5707963267948959 0 0</pose>
          <geometry>
            <cylinder>
              <length>0.10000000000000001</length>
              <radius>0.050000000000000003</radius>
            </cylinder>
          </geometry>
          <surface>
            <friction>
              <ode/>
            </friction>
            <bounce/>
            <contact/>
          </surface>
        </collision>
        <visual name='rear_right_wheel_link_fixed_joint_lump__visual_2_visual'>
          <pose>0 0 0 1.5707963267948959 0 0</pose>
          <geometry>
            <cylinder>
              <length>0.10000000000000001</length>
              <radius>0.050000000000000003</radius>
            </cylinder>
          </geometry>
          <material>
            <diffuse>1 0 0 1</diffuse>
            <ambient>1 0 0 1</ambient>
          </material>
        </visual>
        <enable_wind>false</enable_wind>
      </link>
      <frame name='root_base_joint' attached_to='base_link'>
        <pose>0 0 0.14999999999999999 0 0 0</pose>
      </frame>
      <frame name='root_link' attached_to='root_base_joint'>
        <pose>0 0 0 0 0 0</pose>
      </frame>
      <frame name='bob_cartpole_joint' attached_to='cartpole_link'>
        <pose>0 0 0.40000000000000002 0 0 0</pose>
      </frame>
      <frame name='bob_link' attached_to='bob_cartpole_joint'>
        <pose>0 0 0 0 0 0</pose>
      </frame>
      <pose>-1.5008390384418604e-23 -4.9978272794295565e-23 -3.2605587544157215e-11 2.7601813337771729e-21 3.7726061837537096e-23 -5.5578887033202014e-22</pose>
      <static>false</static>
      <self_collide>false</self_collide>
      <plugin filename = "gz-sim-pose-publisher-system" name = "gz::sim::systems::PosePublisher">
        <publish_link_pose>true</publish_link_pose>
        <update_frequency>-1</update_frequency>
        <use_pose_vector_msg>true</use_pose_vector_msg>
      </plugin>
      <plugin filename = "gz-sim-joint-state-publisher-system" name = "gz::sim::systems::JointStatePublisher">
      </plugin>
      <plugin filename = "gz-sim-diff-drive-system" name = "gz::sim::systems::DiffDrive">
        <left_joint>rear_left_wheel_joint</left_joint>
        <right_joint>rear_right_wheel_joint</right_joint>
        <wheel_seperation>0.4</wheel_seperation>
        <wheel_radius>0.05</wheel_radius>
      </plugin>
    </model>
    
    <light name='sun' type='directional'>
      <pose>0 0 10 0 0 0</pose>
      <cast_shadows>true</cast_shadows>
      <intensity>1</intensity>
      <direction>-0.5 0.10000000000000001 -0.90000000000000002</direction>
      <diffuse>0.800000012 0.800000012 0.800000012 1</diffuse>
      <specular>0.200000003 0.200000003 0.200000003 1</specular>
      <attenuation>
        <range>1000</range>
        <linear>0.01</linear>
        <constant>0.90000000000000002</constant>
        <quadratic>0.001</quadratic>
      </attenuation>
      <spot>
        <inner_angle>0</inner_angle>
        <outer_angle>0</outer_angle>
        <falloff>0</falloff>
      </spot>
    </light>
  </world>
</sdf>
